<mujoco>
  <option gravity = "0 0 -9.81"/>
	<worldbody>
	<light diffuse=".5 .5 .5" pos="0 0 3" dir="0 0 -1"/>
	<geom type="plane" size="1 1 0.1" rgba="0 .9 0 1" />
  <body name="name1" pos="0 0 0.3">
    <geom name="name2" type="box" size=".3 .3 .3" rgba=".9 0 1 1"/> 
    <joint name="y-joint" type="slide" axis="0 1 0"/>
    <joint name="x-joint" type="slide" axis="1 0 0"/>
	</body>
  <body pos="0 2 0.15">
    <geom type="sphere" size = "0.15"/>
    <joint type="free"/>
  </body>
  </worldbody>
  <actuator>
    <position name="y-position" joint="y-joint" kp="10000"/>
  </actuator>
</mujoco>
