<?xml version="1.0"?>
<robot name="prismatic_box_robot">
  <!-- Base link -->
  <link name="base_link"/>

  <!-- The box link -->
  <link name="moving_box">
    <visual>
      <origin xyz="0 0 1"/  >
      <geometry>
        <box size="1 1 1"/>
      </geometry>
      <material name="grey">
        <color rgba="0.5 0.5 0.5 1"/>
      </material>
    </visual>
  </link>

  <!-- Prismatic joint for x-axis movement -->
  <joint name="x_prismatic_joint" type="prismatic">
    <parent link="base_link"/>
    <child link="moving_box"/>
    <origin xyz="0 0 0" rpy="0 0 0"/>
    <axis xyz="1 0 0"/>
    <limit lower="-1.0" upper="1.0" effort="10" velocity="0.5"/>
  </joint>

  <!-- Prismatic joint for y-axis movement -->
  <joint name="y_prismatic_joint" type="prismatic">
    <parent link="moving_box"/>
    <child link="moving_box"/>
    <origin xyz="0 0 0" rpy="0 0 0"/>
    <axis xyz="0 1 0"/>
    <limit lower="-1.0" upper="1.0" effort="10" velocity="0.5"/>
  </joint>
</robot>

